<?xml version="1.0"?>
<robot xmlns:xacro="http://www.ros.org/wiki/xacro">
  <!-- Include the inertial_macros.xacro file -->
  <xacro:include filename="$(find mobRobURDF_description)/urdf/macros/inertial_macros.xacro" />

  <!-- Base Link -->
  <link name="base_link"></link>

  <!-- Chassis Macro -->
  <xacro:macro name="chassis" params="size mass material x_steer y_steer z_steer">
    <xacro:property name="size_list" value="${list(map(float, size.split()))}" />
    <xacro:property name="l" value="${size_list[0]}" />
    <xacro:property name="w" value="${size_list[1]}" />
    <xacro:property name="h" value="${size_list[2]}" />

    <link name="chassis">
      <inertial>
        <mass value="${mass}" />
        <origin xyz="0 0 0" rpy="0 0 0" />
        <xacro:box_inertia mass="${mass}" l="${l}" w="${w}" h="${h}" />
      </inertial>
      <visual>
        <origin xyz="0 0 0" rpy="0 0 0" />
        <geometry>
          <box size="${l} ${w} ${h}" />
        </geometry>
        <material name="${material}" />
      </visual>
      <collision>
        <origin xyz="0 0 0" rpy="0 0 0" />
        <geometry>
          <box size="${l} ${w} ${h}" />
        </geometry>
      </collision>
    </link>

    <!-- Fixed Joint between base_link and chassis -->
    <joint name="base_to_chassis" type="fixed">
      <parent link="base_link" />
      <child link="chassis" />
      <origin xyz="0 0 ${h/2}" rpy="0 0 0" />
    </joint>

    <!-- Front Steering Link (Left) for 4-Wheeled Robot (when ackermann control is chosen) -->
    <link name="front_left_steering_link">
      <!-- No mass or geometry needed -->
      <inertial>
        <mass value="0.001" /> <!-- Minimal mass to avoid simulation issues -->
        <origin xyz="0 0 0" rpy="0 0 0" />
        <inertia ixx="1e-6" ixy="0" ixz="0" iyy="1e-6" iyz="0" izz="1e-6" />
      </inertial>
    </link>

    <!-- Revolute Joint for Steering (z-axis rotation | Left) -->
    <joint name="chassis_to_front_left_steering" type="revolute">
      <parent link="chassis" />
      <child link="front_left_steering_link" />
      <origin xyz="${x_steer} ${y_steer} ${z_steer}" rpy="0 0 0" /> <!-- Position at front wheel base -->
      <axis xyz="0 0 1" /> <!-- Rotation around z-axis for steering -->
      <limit lower="${-pi/4}" upper="${pi/4}" effort="100" velocity="10" /> <!-- Steering range: ±90° -->
    </joint>

    <!-- Front Steering Link (Right) for 4-Wheeled Robot (when ackermann control is chosen) -->
    <link name="front_right_steering_link">
      <!-- No mass or geometry needed -->
      <inertial>
        <mass value="0.001" /> <!-- Minimal mass to avoid simulation issues -->
        <origin xyz="0 0 0" rpy="0 0 0" />
        <inertia ixx="1e-6" ixy="0" ixz="0" iyy="1e-6" iyz="0" izz="1e-6" />
      </inertial>
    </link>

    <!-- Revolute Joint for Steering (z-axis rotation | Right) -->
    <joint name="chassis_to_front_right_steering" type="revolute">
      <parent link="chassis" />
      <child link="front_right_steering_link" />
      <origin xyz="${x_steer} -${y_steer} ${z_steer}" rpy="0 0 0" /> <!-- Position at front wheel base -->
      <axis xyz="0 0 1" /> <!-- Rotation around z-axis for steering -->
      <limit lower="${-pi/4}" upper="${pi/4}" effort="100" velocity="10" /> <!-- Steering range: ±90° -->
    </joint>

  </xacro:macro>
</robot>