<?xml version="1.0"?>
<robot xmlns:xacro="http://www.ros.org/wiki/xacro">
  <!-- Include the inertial_macros.xacro file -->
  <xacro:include filename="$(find mobRobURDF_description)/urdf/macros/inertial_macros.xacro" />

  <!-- Wheel Macro (Cylindrical) -->
  <xacro:macro name="wheel" params="name radius width mass material x y z">
    <link name="${name}_wheel">
      <inertial>
        <mass value="${mass}" />
        <origin xyz="0 0 0" rpy="${pi/2} 0 0" />
        <!-- Use the cylinder_inertia macro from inertial_macros.xacro -->
        <xacro:cylinder_inertia mass="${mass}" r="${radius}" h="${width}" />
      </inertial>
      <visual>
        <origin xyz="0 0 0" rpy="${pi/2} 0 0" />
        <geometry>
          <cylinder radius="${radius}" length="${width}" />
        </geometry>
        <material name="${material}" />
      </visual>
      <collision>
        <origin xyz="0 0 0" rpy="${pi/2} 0 0" />
        <geometry>
          <cylinder radius="${radius}" length="${width}" />
        </geometry>
      </collision>
    </link>
    <joint name="${name}_joint" type="continuous">
      <parent link="chassis" />
      <child link="${name}_wheel" />
      <origin xyz="${x} ${y} ${z}" rpy="0 0 0" />
      <axis xyz="0 1 0" />
    </joint>
  </xacro:macro>

  <!-- Caster Macro (Spherical) -->
  <xacro:macro name="caster" params="name radius mass material x y z">
    <link name="${name}_wheel">
      <inertial>
        <mass value="${mass}" />
        <origin xyz="0 0 0" rpy="0 0 0" />
        <!-- Use the sphere_inertia macro from inertial_macros.xacro -->
        <xacro:sphere_inertia mass="${mass}" r="${radius}" />
      </inertial>
      <visual>
        <origin xyz="0 0 0" rpy="0 0 0" />
        <geometry>
          <sphere radius="${radius}" />
        </geometry>
        <material name="${material}" />
      </visual>
      <collision>
        <origin xyz="0 0 0" rpy="0 0 0" />
        <geometry>
          <sphere radius="${radius}" />
        </geometry>
      </collision>
    </link>

    <joint name="${name}_joint" type="continuous">
      <parent link="free-rotating_y_link" />
      <child link="${name}_wheel" />
      <origin xyz="0 0 0" rpy="0 0 0" />
      <axis xyz="0 0 1" />
    </joint>

    <!-- Front free-rotating Link (around y) for 2-Wheeled Robot -->
    <link name="free-rotating_y_link">
      <!-- No mass or geometry needed -->
      <inertial>
        <mass value="0.001" /> <!-- Minimal mass to avoid simulation issues -->
        <origin xyz="0 0 0" rpy="0 0 0" />
        <inertia ixx="1e-6" ixy="0" ixz="0" iyy="1e-6" iyz="0" izz="1e-6" />
      </inertial>
    </link>

    <joint name="free-rotating_y_joint" type="continuous">
      <parent link="free-rotating_x_link" />
      <child link="free-rotating_y_link" />
      <origin xyz="0 0 0" rpy="0 0 0" />
      <axis xyz="0 1 0" />
    </joint>

    <!-- Front free-rotating Link (around x) for 2-Wheeled Robot -->
    <link name="free-rotating_x_link">
      <!-- No mass or geometry needed -->
      <inertial>
        <mass value="0.001" /> <!-- Minimal mass to avoid simulation issues -->
        <origin xyz="0 0 0" rpy="0 0 0" />
        <inertia ixx="1e-6" ixy="0" ixz="0" iyy="1e-6" iyz="0" izz="1e-6" />
      </inertial>
    </link>

    <joint name="free-rotating_x_joint" type="continuous">
      <parent link="chassis" />
      <child link="free-rotating_x_link" />
      <origin xyz="${x} ${y} ${z}" rpy="0 0 0" />
      <axis xyz="1 0 0" />
    </joint>
  </xacro:macro>
</robot>