<?xml version="1.0" ?>
<!-- =================================================================================== -->
<!-- |    This document was autogenerated by xacro from /home/alip22/Mobile_Robot_URDF_Maker/build/mobRobURDF_wizard/mobRobURDF_wizard/classes/temp/mobRob.xacro | -->
<!-- |    EDITING THIS FILE BY HAND IS NOT RECOMMENDED                                 | -->
<!-- =================================================================================== -->
<robot name="mobRob">
  <!-- Base Link -->
  <link name="base_link"/>
  <!-- <xacro:include filename="$(find mobRobURDF_description)/urdf/gazebo_files/gazebo_sensors.xacro" /> -->
  <material name="Gray">
    <color rgba="0.5 0.5 0.5 1.0"/>
  </material>
  <material name="Black">
    <color rgba="0.0 0.0 0.0 1.0"/>
  </material>
  <material name="Red">
    <color rgba="1.0 0.0 0.0 1.0"/>
  </material>
  <material name="Blue">
    <color rgba="0.0 0.0 1.0 1.0"/>
  </material>
  <material name="Green">
    <color rgba="0.0 1.0 0.0 1.0"/>
  </material>
  <material name="White">
    <color rgba="1.0 1.0 1.0 1.0"/>
  </material>
  <link name="chassis">
    <inertial>
      <mass value="5"/>
      <origin rpy="0 0 0" xyz="0 0 0"/>
      <inertia ixx="0.19270833333333334" ixy="0" ixz="0" iyy="0.43333333333333335" iyz="0" izz="0.5927083333333334"/>
    </inertial>
    <visual>
      <origin rpy="0 0 0" xyz="0 0 0"/>
      <geometry>
        <box size="1.0 0.65 0.2"/>
      </geometry>
      <material name="Gray"/>
    </visual>
    <collision>
      <origin rpy="0 0 0" xyz="0 0 0"/>
      <geometry>
        <box size="1.0 0.65 0.2"/>
      </geometry>
    </collision>
  </link>
  <!-- Fixed Joint between base_link and chassis -->
  <joint name="base_to_chassis" type="fixed">
    <parent link="base_link"/>
    <child link="chassis"/>
    <origin rpy="0 0 0" xyz="0 0 0.1"/>
  </joint>
  <link name="front_left_wheel">
    <inertial>
      <mass value="0.3"/>
      <origin rpy="1.5707963267948966 0 0" xyz="0 0 0"/>
      <inertia ixx="0.0025900000000000003" ixy="0" ixz="0" iyy="0.0025900000000000003" iyz="0" izz="0.00486"/>
    </inertial>
    <visual>
      <origin rpy="1.5707963267948966 0 0" xyz="0 0 0"/>
      <geometry>
        <cylinder length="0.08" radius="0.18"/>
      </geometry>
      <material name="Black"/>
    </visual>
    <collision>
      <origin rpy="1.5707963267948966 0 0" xyz="0 0 0"/>
      <geometry>
        <cylinder length="0.08" radius="0.18"/>
      </geometry>
    </collision>
  </link>
  <joint name="front_left_joint" type="continuous">
    <parent link="chassis"/>
    <child link="front_left_wheel"/>
    <origin rpy="0 0 0" xyz="0.5 0.365 -0.1"/>
    <axis xyz="0 1 0"/>
  </joint>
  <link name="front_right_wheel">
    <inertial>
      <mass value="0.3"/>
      <origin rpy="1.5707963267948966 0 0" xyz="0 0 0"/>
      <inertia ixx="0.0025900000000000003" ixy="0" ixz="0" iyy="0.0025900000000000003" iyz="0" izz="0.00486"/>
    </inertial>
    <visual>
      <origin rpy="1.5707963267948966 0 0" xyz="0 0 0"/>
      <geometry>
        <cylinder length="0.08" radius="0.18"/>
      </geometry>
      <material name="Black"/>
    </visual>
    <collision>
      <origin rpy="1.5707963267948966 0 0" xyz="0 0 0"/>
      <geometry>
        <cylinder length="0.08" radius="0.18"/>
      </geometry>
    </collision>
  </link>
  <joint name="front_right_joint" type="continuous">
    <parent link="chassis"/>
    <child link="front_right_wheel"/>
    <origin rpy="0 0 0" xyz="0.5 -0.365 -0.1"/>
    <axis xyz="0 1 0"/>
  </joint>
  <link name="rear_left_wheel">
    <inertial>
      <mass value="0.3"/>
      <origin rpy="1.5707963267948966 0 0" xyz="0 0 0"/>
      <inertia ixx="0.0025900000000000003" ixy="0" ixz="0" iyy="0.0025900000000000003" iyz="0" izz="0.00486"/>
    </inertial>
    <visual>
      <origin rpy="1.5707963267948966 0 0" xyz="0 0 0"/>
      <geometry>
        <cylinder length="0.08" radius="0.18"/>
      </geometry>
      <material name="Black"/>
    </visual>
    <collision>
      <origin rpy="1.5707963267948966 0 0" xyz="0 0 0"/>
      <geometry>
        <cylinder length="0.08" radius="0.18"/>
      </geometry>
    </collision>
  </link>
  <joint name="rear_left_joint" type="continuous">
    <parent link="chassis"/>
    <child link="rear_left_wheel"/>
    <origin rpy="0 0 0" xyz="-0.5 0.365 -0.1"/>
    <axis xyz="0 1 0"/>
  </joint>
  <link name="rear_right_wheel">
    <inertial>
      <mass value="0.3"/>
      <origin rpy="1.5707963267948966 0 0" xyz="0 0 0"/>
      <inertia ixx="0.0025900000000000003" ixy="0" ixz="0" iyy="0.0025900000000000003" iyz="0" izz="0.00486"/>
    </inertial>
    <visual>
      <origin rpy="1.5707963267948966 0 0" xyz="0 0 0"/>
      <geometry>
        <cylinder length="0.08" radius="0.18"/>
      </geometry>
      <material name="Black"/>
    </visual>
    <collision>
      <origin rpy="1.5707963267948966 0 0" xyz="0 0 0"/>
      <geometry>
        <cylinder length="0.08" radius="0.18"/>
      </geometry>
    </collision>
  </link>
  <joint name="rear_right_joint" type="continuous">
    <parent link="chassis"/>
    <child link="rear_right_wheel"/>
    <origin rpy="0 0 0" xyz="-0.5 -0.365 -0.1"/>
    <axis xyz="0 1 0"/>
  </joint>
  <link name="lidar">
    <inertial>
      <mass value="0.2"/>
      <origin rpy="0 0 0" xyz="0 0 0"/>
      <inertia ixx="0.0005116666666666667" ixy="0" ixz="0" iyy="0.0005116666666666667" iyz="0" izz="0.00081"/>
    </inertial>
    <visual>
      <origin rpy="0 0 0" xyz="0 0 0"/>
      <geometry>
        <cylinder length="0.08" radius="0.09"/>
      </geometry>
      <material name="Red"/>
    </visual>
    <collision>
      <origin rpy="0 0 0" xyz="0 0 0"/>
      <geometry>
        <cylinder length="0.08" radius="0.09"/>
      </geometry>
    </collision>
  </link>
  <joint name="lidar_joint" type="fixed">
    <parent link="chassis"/>
    <child link="lidar"/>
    <origin rpy="0 0 0" xyz="0 0 0.14"/>
  </joint>
  <!-- Camera Frame -->
  <link name="camera">
    <inertial>
      <mass value="0.1"/>
      <origin rpy="0 0 0" xyz="0 0 0"/>
      <inertia ixx="0.00011333333333333334" ixy="0" ixz="0" iyy="5.083333333333334e-05" iyz="0" izz="0.00010416666666666669"/>
    </inertial>
    <visual>
      <origin rpy="0 0 0" xyz="0 0 0"/>
      <geometry>
        <box size="0.05 0.1 0.06"/>
      </geometry>
      <material name="Blue"/>
    </visual>
    <collision>
      <origin rpy="0 0 0" xyz="0 0 0"/>
      <geometry>
        <box size="0.05 0.1 0.06"/>
      </geometry>
    </collision>
  </link>
  <joint name="camera_joint" type="fixed">
    <parent link="chassis"/>
    <child link="camera"/>
    <origin rpy="0 0 0" xyz="0.525 0 0"/>
  </joint>
  <!-- Camera Optical Frame -->
  <link name="camera_optical"/>
  <joint name="camera_optical_joint" type="fixed">
    <parent link="camera"/>
    <child link="camera_optical"/>
    <!-- Rotate to align with ROS optical frame convention:
           X: Right, Y: Down, Z: Forward -->
    <origin rpy="-1.5707963267948966 0 -1.5707963267948966" xyz="0 0 0"/>
  </joint>
</robot>
