<?xml version="1.0" ?>
<!-- =================================================================================== -->
<!-- |    This document was autogenerated by xacro from /home/alip22/Mobile_Robot_URDF_Maker/install/mobRobURDF_description/share/mobRobURDF_description/urdf/temp/3_wheeled/mobRob.xacro | -->
<!-- |    EDITING THIS FILE BY HAND IS NOT RECOMMENDED                                 | -->
<!-- =================================================================================== -->
<robot name="mobRob">
  <!-- Base Link -->
  <link name="base_link"/>
  <!-- <xacro:include filename="$(find mobRobURDF_description)/urdf/gazebo_files/gazebo_sensors.xacro" /> -->
  <material name="Gray">
    <color rgba="0.5 0.5 0.5 1.0"/>
  </material>
  <material name="Black">
    <color rgba="0.0 0.0 0.0 1.0"/>
  </material>
  <material name="Red">
    <color rgba="1.0 0.0 0.0 1.0"/>
  </material>
  <material name="Blue">
    <color rgba="0.0 0.0 1.0 1.0"/>
  </material>
  <material name="Green">
    <color rgba="0.0 1.0 0.0 1.0"/>
  </material>
  <material name="White">
    <color rgba="1.0 1.0 1.0 1.0"/>
  </material>
  <!-- Chassis Link -->
  <link name="chassis">
    <inertial>
      <mass value="1.0"/>
      <origin rpy="0 0 0" xyz="0 0 0"/>
      <inertia ixx="0.06083333333333334" ixy="0" ixz="0" iyy="0.1275" iyz="0" izz="0.17333333333333334"/>
    </inertial>
    <visual>
      <origin rpy="0 0 0" xyz="0 0 0"/>
      <geometry>
        <box size="1.2 0.8 0.3"/>
      </geometry>
      <material name="Gray"/>
    </visual>
    <collision>
      <origin rpy="0 0 0" xyz="0 0 0"/>
      <geometry>
        <box size="1.2 0.8 0.3"/>
      </geometry>
    </collision>
  </link>
  <!-- Fixed Joint between base_link and chassis -->
  <joint name="base_to_chassis" type="fixed">
    <parent link="base_link"/>
    <child link="chassis"/>
    <origin rpy="0 0 0" xyz="0 0 0.15"/>
  </joint>
  <!-- Front Steering Link for 3-Wheeled Robot -->
  <link name="front_steering_link">
    <!-- No mass or geometry needed; this is a pivot point for steering -->
    <inertial>
      <mass value="0.001"/>
      <!-- Minimal mass to avoid simulation issues -->
      <origin rpy="0 0 0" xyz="0 0 0"/>
      <inertia ixx="1e-6" ixy="0" ixz="0" iyy="1e-6" iyz="0" izz="1e-6"/>
    </inertial>
    <!-- Optional: Add visual/collision if you want a visible steering component -->
  </link>
  <!-- Revolute Joint for Steering (z-axis rotation) -->
  <joint name="chassis_to_front_steering" type="revolute">
    <parent link="chassis"/>
    <child link="front_steering_link"/>
    <origin rpy="0 0 0" xyz="0.6 0 -0.15"/>
    <!-- Position at front wheel base -->
    <axis xyz="0 0 1"/>
    <!-- Rotation around z-axis for steering -->
    <limit effort="100" lower="-1.5707963267948966" upper="1.5707963267948966" velocity="10"/>
    <!-- Steering range: ±90° -->
  </joint>
  <link name="front_wheel">
    <inertial>
      <mass value="0.5"/>
      <origin rpy="1.5707963267948966 0 0" xyz="0 0 0"/>
      <inertia ixx="0.005600000000000001" ixy="0" ixz="0" iyy="0.005600000000000001" iyz="0" izz="0.010000000000000002"/>
    </inertial>
    <visual>
      <origin rpy="1.5707963267948966 0 0" xyz="0 0 0"/>
      <geometry>
        <cylinder length="0.12" radius="0.2"/>
      </geometry>
      <material name="Black"/>
    </visual>
    <collision>
      <origin rpy="1.5707963267948966 0 0" xyz="0 0 0"/>
      <geometry>
        <cylinder length="0.12" radius="0.2"/>
      </geometry>
    </collision>
  </link>
  <joint name="front_joint" type="continuous">
    <parent link="front_steering_link"/>
    <child link="front_wheel"/>
    <origin rpy="0 0 0" xyz="0 0 0"/>
    <axis xyz="0 1 0"/>
  </joint>
  <link name="rear_left_wheel">
    <inertial>
      <mass value="0.5"/>
      <origin rpy="1.5707963267948966 0 0" xyz="0 0 0"/>
      <inertia ixx="0.005600000000000001" ixy="0" ixz="0" iyy="0.005600000000000001" iyz="0" izz="0.010000000000000002"/>
    </inertial>
    <visual>
      <origin rpy="1.5707963267948966 0 0" xyz="0 0 0"/>
      <geometry>
        <cylinder length="0.12" radius="0.2"/>
      </geometry>
      <material name="Black"/>
    </visual>
    <collision>
      <origin rpy="1.5707963267948966 0 0" xyz="0 0 0"/>
      <geometry>
        <cylinder length="0.12" radius="0.2"/>
      </geometry>
    </collision>
  </link>
  <joint name="rear_left_joint" type="continuous">
    <parent link="chassis"/>
    <child link="rear_left_wheel"/>
    <origin rpy="0 0 0" xyz="-0.4666666666666667 0.46 -0.15"/>
    <axis xyz="0 1 0"/>
  </joint>
  <link name="rear_right_wheel">
    <inertial>
      <mass value="0.5"/>
      <origin rpy="1.5707963267948966 0 0" xyz="0 0 0"/>
      <inertia ixx="0.005600000000000001" ixy="0" ixz="0" iyy="0.005600000000000001" iyz="0" izz="0.010000000000000002"/>
    </inertial>
    <visual>
      <origin rpy="1.5707963267948966 0 0" xyz="0 0 0"/>
      <geometry>
        <cylinder length="0.12" radius="0.2"/>
      </geometry>
      <material name="Black"/>
    </visual>
    <collision>
      <origin rpy="1.5707963267948966 0 0" xyz="0 0 0"/>
      <geometry>
        <cylinder length="0.12" radius="0.2"/>
      </geometry>
    </collision>
  </link>
  <joint name="rear_right_joint" type="continuous">
    <parent link="chassis"/>
    <child link="rear_right_wheel"/>
    <origin rpy="0 0 0" xyz="-0.4666666666666667 -0.46 -0.15"/>
    <axis xyz="0 1 0"/>
  </joint>
  <link name="lidar">
    <inertial>
      <mass value="0.2"/>
      <origin rpy="0 0 0" xyz="0 0 0"/>
      <inertia ixx="0.0006066666666666668" ixy="0" ixz="0" iyy="0.0006066666666666668" iyz="0" izz="0.0010000000000000002"/>
    </inertial>
    <visual>
      <origin rpy="0 0 0" xyz="0 0 0"/>
      <geometry>
        <cylinder length="0.08" radius="0.1"/>
      </geometry>
      <material name="Red"/>
    </visual>
    <collision>
      <origin rpy="0 0 0" xyz="0 0 0"/>
      <geometry>
        <cylinder length="0.08" radius="0.1"/>
      </geometry>
    </collision>
  </link>
  <joint name="lidar_joint" type="fixed">
    <parent link="chassis"/>
    <child link="lidar"/>
    <origin rpy="0 0 0" xyz="0 0 0.19"/>
  </joint>
  <!-- Camera Frame -->
  <link name="camera">
    <inertial>
      <mass value="0.1"/>
      <origin rpy="0 0 0" xyz="0 0 0"/>
      <inertia ixx="0.0003866666666666667" ixy="0" ixz="0" iyy="0.00010666666666666668" iyz="0" izz="0.0003866666666666667"/>
    </inertial>
    <visual>
      <origin rpy="0 0 0" xyz="0 0 0"/>
      <geometry>
        <box size="0.08 0.2 0.08"/>
      </geometry>
      <material name="Blue"/>
    </visual>
    <collision>
      <origin rpy="0 0 0" xyz="0 0 0"/>
      <geometry>
        <box size="0.08 0.2 0.08"/>
      </geometry>
    </collision>
  </link>
  <joint name="camera_joint" type="fixed">
    <parent link="chassis"/>
    <child link="camera"/>
    <origin rpy="0 0 0" xyz="0.64 0 0.10999999999999999"/>
  </joint>
  <!-- Camera Optical Frame -->
  <link name="camera_optical"/>
  <joint name="camera_optical_joint" type="fixed">
    <parent link="camera"/>
    <child link="camera_optical"/>
    <!-- Rotate to align with ROS optical frame convention:
           X: Right, Y: Down, Z: Forward -->
    <origin rpy="-1.5707963267948966 0 -1.5707963267948966" xyz="0 0 0"/>
  </joint>
</robot>
