<?xml version="1.0" ?>
<!-- =================================================================================== -->
<!-- |    This document was autogenerated by xacro from /home/alip/Mobile_Robot_URDF_Maker/install/mobRobURDF_description/share/mobRobURDF_description/urdf/temp/2_wheeled_caster/diff_2wc/mobRob_2wc_diff.xacro | -->
<!-- |    EDITING THIS FILE BY HAND IS NOT RECOMMENDED                                 | -->
<!-- =================================================================================== -->
<robot>
  <!-- Base Link -->
  <link name="base_link"/>
  <material name="Gray">
    <color rgba="0.5 0.5 0.5 1.0"/>
  </material>
  <material name="Black">
    <color rgba="0.0 0.0 0.0 1.0"/>
  </material>
  <material name="Red">
    <color rgba="1.0 0.0 0.0 1.0"/>
  </material>
  <material name="Blue">
    <color rgba="0.0 0.0 1.0 1.0"/>
  </material>
  <material name="Green">
    <color rgba="0.0 1.0 0.0 1.0"/>
  </material>
  <material name="White">
    <color rgba="1.0 1.0 1.0 1.0"/>
  </material>
  <!-- Chassis Link -->
  <link name="chassis">
    <inertial>
      <mass value="1.0"/>
      <origin rpy="0 0 0" xyz="0 0 0"/>
      <inertia ixx="0.06083333333333334" ixy="0" ixz="0" iyy="0.1275" iyz="0" izz="0.17333333333333334"/>
    </inertial>
    <visual>
      <origin rpy="0 0 0" xyz="0 0 0"/>
      <geometry>
        <box size="1.2 0.8 0.3"/>
      </geometry>
      <material name="Gray"/>
    </visual>
    <collision>
      <origin rpy="0 0 0" xyz="0 0 0"/>
      <geometry>
        <box size="1.2 0.8 0.3"/>
      </geometry>
    </collision>
  </link>
  <!-- Fixed Joint between base_link and chassis -->
  <joint name="base_to_chassis" type="fixed">
    <parent link="base_link"/>
    <child link="chassis"/>
    <origin rpy="0 0 0" xyz="0 0 0.15"/>
  </joint>
  <link name="left_wheel">
    <inertial>
      <mass value="0.5"/>
      <origin rpy="1.5707963267948966 0 0" xyz="0 0 0"/>
      <inertia ixx="0.00665" ixy="0" ixz="0" iyy="0.00665" iyz="0" izz="0.0121"/>
    </inertial>
    <visual>
      <origin rpy="1.5707963267948966 0 0" xyz="0 0 0"/>
      <geometry>
        <cylinder length="0.12" radius="0.22"/>
      </geometry>
      <material name="Black"/>
    </visual>
    <collision>
      <origin rpy="1.5707963267948966 0 0" xyz="0 0 0"/>
      <geometry>
        <cylinder length="0.12" radius="0.22"/>
      </geometry>
    </collision>
  </link>
  <joint name="left_joint" type="continuous">
    <parent link="chassis"/>
    <child link="left_wheel"/>
    <origin rpy="0 0 0" xyz="-0.3 0.46 -0.15"/>
    <axis xyz="0 1 0"/>
  </joint>
  <link name="right_wheel">
    <inertial>
      <mass value="0.5"/>
      <origin rpy="1.5707963267948966 0 0" xyz="0 0 0"/>
      <inertia ixx="0.00665" ixy="0" ixz="0" iyy="0.00665" iyz="0" izz="0.0121"/>
    </inertial>
    <visual>
      <origin rpy="1.5707963267948966 0 0" xyz="0 0 0"/>
      <geometry>
        <cylinder length="0.12" radius="0.22"/>
      </geometry>
      <material name="Black"/>
    </visual>
    <collision>
      <origin rpy="1.5707963267948966 0 0" xyz="0 0 0"/>
      <geometry>
        <cylinder length="0.12" radius="0.22"/>
      </geometry>
    </collision>
  </link>
  <joint name="right_joint" type="continuous">
    <parent link="chassis"/>
    <child link="right_wheel"/>
    <origin rpy="0 0 0" xyz="-0.3 -0.46 -0.15"/>
    <axis xyz="0 1 0"/>
  </joint>
  <link name="front_caster_wheel">
    <inertial>
      <mass value="0.5"/>
      <origin rpy="0 0 0" xyz="0 0 0"/>
      <inertia ixx="0.00968" ixy="0" ixz="0" iyy="0.00968" iyz="0" izz="0.00968"/>
    </inertial>
    <visual>
      <origin rpy="0 0 0" xyz="0 0 0"/>
      <geometry>
        <sphere radius="0.22"/>
      </geometry>
      <material name="Black"/>
    </visual>
    <collision>
      <origin rpy="0 0 0" xyz="0 0 0"/>
      <geometry>
        <sphere radius="0.22"/>
      </geometry>
    </collision>
  </link>
  <joint name="front_caster_joint" type="continuous">
    <parent link="free-rotating_y_link"/>
    <child link="front_caster_wheel"/>
    <origin rpy="0 0 0" xyz="0 0 0"/>
    <axis xyz="0 0 1"/>
  </joint>
  <!-- Front free-rotating Link (around y) for 2-Wheeled Robot -->
  <link name="free-rotating_y_link">
    <!-- No mass or geometry needed -->
    <inertial>
      <mass value="0.001"/>
      <!-- Minimal mass to avoid simulation issues -->
      <origin rpy="0 0 0" xyz="0 0 0"/>
      <inertia ixx="1e-6" ixy="0" ixz="0" iyy="1e-6" iyz="0" izz="1e-6"/>
    </inertial>
  </link>
  <joint name="free-rotating_y_joint" type="continuous">
    <parent link="free-rotating_x_link"/>
    <child link="free-rotating_y_link"/>
    <origin rpy="0 0 0" xyz="0 0 0"/>
    <axis xyz="0 1 0"/>
  </joint>
  <!-- Front free-rotating Link (around x) for 2-Wheeled Robot -->
  <link name="free-rotating_x_link">
    <!-- No mass or geometry needed -->
    <inertial>
      <mass value="0.001"/>
      <!-- Minimal mass to avoid simulation issues -->
      <origin rpy="0 0 0" xyz="0 0 0"/>
      <inertia ixx="1e-6" ixy="0" ixz="0" iyy="1e-6" iyz="0" izz="1e-6"/>
    </inertial>
  </link>
  <joint name="free-rotating_x_joint" type="continuous">
    <parent link="chassis"/>
    <child link="free-rotating_x_link"/>
    <origin rpy="0 0 0" xyz="0.38 0 -0.15"/>
    <axis xyz="1 0 0"/>
  </joint>
  <link name="lidar">
    <inertial>
      <mass value="0.2"/>
      <origin rpy="0 0 0" xyz="0 0 0"/>
      <inertia ixx="0.0006066666666666668" ixy="0" ixz="0" iyy="0.0006066666666666668" iyz="0" izz="0.0010000000000000002"/>
    </inertial>
    <visual>
      <origin rpy="0 0 0" xyz="0 0 0"/>
      <geometry>
        <cylinder length="0.08" radius="0.1"/>
      </geometry>
      <material name="Red"/>
    </visual>
    <collision>
      <origin rpy="0 0 0" xyz="0 0 0"/>
      <geometry>
        <cylinder length="0.08" radius="0.1"/>
      </geometry>
    </collision>
  </link>
  <joint name="lidar_joint" type="fixed">
    <parent link="chassis"/>
    <child link="lidar"/>
    <origin rpy="0 0 0" xyz="0 0 0.19"/>
  </joint>
  <!-- Camera Frame -->
  <link name="camera">
    <inertial>
      <mass value="0.1"/>
      <origin rpy="0 0 0" xyz="0 0 0"/>
      <inertia ixx="0.0003866666666666667" ixy="0" ixz="0" iyy="0.00010666666666666668" iyz="0" izz="0.0003866666666666667"/>
    </inertial>
    <visual>
      <origin rpy="0 0 0" xyz="0 0 0"/>
      <geometry>
        <box size="0.08 0.2 0.08"/>
      </geometry>
      <material name="Blue"/>
    </visual>
    <collision>
      <origin rpy="0 0 0" xyz="0 0 0"/>
      <geometry>
        <box size="0.08 0.2 0.08"/>
      </geometry>
    </collision>
  </link>
  <joint name="camera_joint" type="fixed">
    <parent link="chassis"/>
    <child link="camera"/>
    <origin rpy="0 0 0" xyz="0.64 0 0"/>
  </joint>
  <!-- Camera Optical Frame -->
  <link name="camera_optical"/>
  <joint name="camera_optical_joint" type="fixed">
    <parent link="camera"/>
    <child link="camera_optical"/>
    <!-- Rotate to align with ROS optical frame convention:
           X: Right, Y: Down, Z: Forward -->
    <origin rpy="-1.5707963267948966 0 -1.5707963267948966" xyz="0 0 0"/>
  </joint>
  <ros2_control name="GazeboSystem" type="system">
    <hardware>
      <plugin>gz_ros2_control/GazeboSimSystem</plugin>
    </hardware>
    <joint name="left_joint">
      <command_interface name="velocity">
        <param name="min">-50</param>
        <param name="max">50</param>
      </command_interface>
      <state_interface name="velocity"/>
      <state_interface name="position"/>
    </joint>
    <joint name="right_joint">
      <command_interface name="velocity">
        <param name="min">-50</param>
        <param name="max">50</param>
      </command_interface>
      <state_interface name="velocity"/>
      <state_interface name="position"/>
    </joint>
    <!-- - - - Not-motorized - - - -->
    <joint name="front_caster_joint">
      <command_interface name="velocity"/>
      <state_interface name="position"/>
      <state_interface name="velocity"/>
    </joint>
    <joint name="free-rotating_x_joint">
      <command_interface name="velocity"/>
      <state_interface name="position"/>
      <state_interface name="velocity"/>
    </joint>
    <joint name="free-rotating_y_joint">
      <command_interface name="velocity"/>
      <state_interface name="position"/>
      <state_interface name="velocity"/>
    </joint>
    <!-- - - - - - - - - - - - - - -->
  </ros2_control>
  <gazebo>
    <plugin filename="libgz_ros2_control-system.so" name="gz_ros2_control::GazeboSimROS2ControlPlugin">
      <parameters>/home/alip/Mobile_Robot_URDF_Maker/install/mobRobURDF_control/share/mobRobURDF_control/config/drive/gazebo_controller_diffDrive_2wd_caster.yaml</parameters>
    </plugin>
  </gazebo>
  <!-- Gazebo Lidar Plugin -->
  <gazebo reference="lidar">
    <material>Gazebo/Black</material>
    <sensor name="laser" type="gpu_lidar">
      <pose> 0 0 0 0 0 0 </pose>
      <visualize>true</visualize>
      <update_rate>10</update_rate>
      <lidar>
        <scan>
          <horizontal>
            <samples>360</samples>
            <min_angle>-3.14</min_angle>
            <max_angle>3.14</max_angle>
          </horizontal>
        </scan>
        <range>
          <min>0.3</min>
          <max>12</max>
        </range>
      </lidar>
      <topic>scan</topic>
      <gz_frame_id>laser_frame</gz_frame_id>
    </sensor>
  </gazebo>
  <!-- Gazebo Camera Plugin -->
  <gazebo reference="camera">
    <material>Gazebo/Black</material>
    <sensor name="camera" type="camera">
      <pose> 0 0 0 0 0 0 </pose>
      <visualize>true</visualize>
      <update_rate>10</update_rate>
      <camera>
        <camera_info_topic>camera/camera_info</camera_info_topic>
        <horizontal_fov>1.089</horizontal_fov>
        <image>
          <format>R8G8B8</format>
          <width>640</width>
          <height>480</height>
        </image>
        <clip>
          <near>0.05</near>
          <far>8.0</far>
        </clip>
      </camera>
      <topic>camera/image_raw</topic>
      <gz_frame_id>camera_link_optical</gz_frame_id>
    </sensor>
  </gazebo>
  <!-- Base link properties (common for all controllers) -->
  <gazebo reference="base_link">
    <collision>
      <surface>
        <friction>
          <ode>
            <mu>0.8</mu>
            <mu2>0.8</mu2>
          </ode>
        </friction>
        <contact>
          <kp>1e6</kp>
          <kd>1.0</kd>
          <max_vel>0.1</max_vel>
          <min_depth>0.001</min_depth>
        </contact>
        <bounce>
          <restitution_coefficient>0.0</restitution_coefficient>
        </bounce>
      </surface>
    </collision>
  </gazebo>
  <gazebo reference="left_wheel">
    <collision>
      <surface>
        <friction>
          <ode>
            <mu>1.0</mu>
            <mu2>1.0</mu2>
          </ode>
        </friction>
        <contact>
          <kp>1e6</kp>
          <kd>1.0</kd>
          <max_vel>0.1</max_vel>
          <min_depth>0.001</min_depth>
        </contact>
        <bounce>
          <restitution_coefficient>0.0</restitution_coefficient>
        </bounce>
      </surface>
    </collision>
  </gazebo>
  <gazebo reference="left_joint">
    <damping>0.1</damping>
  </gazebo>
  <gazebo reference="right_wheel">
    <collision>
      <surface>
        <friction>
          <ode>
            <mu>1.0</mu>
            <mu2>1.0</mu2>
          </ode>
        </friction>
        <contact>
          <kp>1e6</kp>
          <kd>1.0</kd>
          <max_vel>0.1</max_vel>
          <min_depth>0.001</min_depth>
        </contact>
        <bounce>
          <restitution_coefficient>0.0</restitution_coefficient>
        </bounce>
      </surface>
    </collision>
  </gazebo>
  <gazebo reference="right_joint">
    <damping>0.1</damping>
  </gazebo>
  <!-- Caster -->
  <gazebo reference="front_caster">
    <collision>
      <surface>
        <friction>
          <ode>
            <mu>0.1</mu>
            <mu2>0.1</mu2>
          </ode>
        </friction>
        <contact>
          <kp>1e6</kp>
          <kd>1.0</kd>
          <max_vel>0.1</max_vel>
          <min_depth>0.001</min_depth>
        </contact>
        <bounce>
          <restitution_coefficient>0.0</restitution_coefficient>
        </bounce>
      </surface>
    </collision>
  </gazebo>
  <gazebo reference="free-rotating_x_joint">
    <damping>0.01</damping>
  </gazebo>
  <gazebo reference="free-rotating_y_joint">
    <damping>0.01</damping>
  </gazebo>
  <gazebo reference="front_caster_joint">
    <damping>0.01</damping>
  </gazebo>
  <!-- Base link properties (common for all controllers) -->
  <gazebo reference="base_link">
    <collision>
      <surface>
        <friction>
          <ode>
            <mu>0.8</mu>
            <mu2>0.8</mu2>
          </ode>
        </friction>
        <contact>
          <kp>1e6</kp>
          <kd>1.0</kd>
          <max_vel>0.1</max_vel>
          <min_depth>0.001</min_depth>
        </contact>
        <bounce>
          <restitution_coefficient>0.0</restitution_coefficient>
        </bounce>
      </surface>
    </collision>
  </gazebo>
  <gazebo reference="left_wheel">
    <collision>
      <surface>
        <friction>
          <ode>
            <mu>1.0</mu>
            <mu2>1.0</mu2>
          </ode>
        </friction>
        <contact>
          <kp>1e6</kp>
          <kd>1.0</kd>
          <max_vel>0.1</max_vel>
          <min_depth>0.001</min_depth>
        </contact>
        <bounce>
          <restitution_coefficient>0.0</restitution_coefficient>
        </bounce>
      </surface>
    </collision>
  </gazebo>
  <gazebo reference="left_joint">
    <damping>0.1</damping>
  </gazebo>
  <gazebo reference="right_wheel">
    <collision>
      <surface>
        <friction>
          <ode>
            <mu>1.0</mu>
            <mu2>1.0</mu2>
          </ode>
        </friction>
        <contact>
          <kp>1e6</kp>
          <kd>1.0</kd>
          <max_vel>0.1</max_vel>
          <min_depth>0.001</min_depth>
        </contact>
        <bounce>
          <restitution_coefficient>0.0</restitution_coefficient>
        </bounce>
      </surface>
    </collision>
  </gazebo>
  <gazebo reference="right_joint">
    <damping>0.1</damping>
  </gazebo>
  <!-- Caster -->
  <gazebo reference="front_caster">
    <collision>
      <surface>
        <friction>
          <ode>
            <mu>0.1</mu>
            <mu2>0.1</mu2>
          </ode>
        </friction>
        <contact>
          <kp>1e6</kp>
          <kd>1.0</kd>
          <max_vel>0.1</max_vel>
          <min_depth>0.001</min_depth>
        </contact>
        <bounce>
          <restitution_coefficient>0.0</restitution_coefficient>
        </bounce>
      </surface>
    </collision>
  </gazebo>
  <gazebo reference="free-rotating_x_joint">
    <damping>0.01</damping>
  </gazebo>
  <gazebo reference="free-rotating_y_joint">
    <damping>0.01</damping>
  </gazebo>
  <gazebo reference="front_caster_joint">
    <damping>0.01</damping>
  </gazebo>
</robot>
